<?xml version="1.0" ?>
<robot name="pi">

    <material name="green">
      <color rgba="0.0 0.8 0.0 1.0"/>
    </material>
    <material name="grey">
      <color rgba="0.2 0.2 0.2 1.0"/>
    </material>
    <material name="orange">
      <color rgba="1.0 0.423529411765 0.0392156862745 1.0"/>
    </material>
    <material name="red">
      <color rgba="0.8 0.0 0.0 1.0"/>
    </material>

    <link name="base">
      <visual>
         <origin rpy="0 0 0" xyz="0 0 0"/>
         <geometry>
           <box size="0.35 0.194 0.10"/>
         </geometry>
         <material name="green"/>
      </visual>
      <collision>
         <origin rpy="0 0 0" xyz="0 0 0"/>
         <geometry>
            <box size="0.35 0.194 0.07"/>
         </geometry>
      </collision>
      <inertial>
        <origin rpy="0 0 0" xyz="0 0 0"/>
        <mass value="1.1"/>
        <inertia ixx="0.00282717" ixy="0.0" ixz="0.0" iyy="0.00677" iyz="0.0" izz="0.0081416"/>
      </inertial>
    </link>

   <!-- FR -->
    <joint name="FR_hip_joint" type="revolute">
      <origin rpy="0 0 0" xyz="0.16 -0.127 0"/>
      <parent link="base"/>
      <child link="FR_hip"/>
      <axis xyz="1 0 0"/>
      <dynamics damping="0.0" friction="0.0"/>
      <limit effort="7" lower="-0.3" upper="0.3" velocity="7"/>
    </joint>
    <link name="FR_hip">
      <visual>
         <origin rpy="0 0 0" xyz="0 0 0"/>
         <geometry>
           <box size="0.04 0.04 0.02"/>
         </geometry>
         <material name="orange"/>
      </visual>
      <collision>
         <origin rpy="0 0 0" xyz="0 0 0"/>
         <geometry>
            <box size="0.04 0.04 0.02"/>
         </geometry>
      </collision>
      <inertial>
        <origin rpy="0 0 0" xyz="0 0 0"/>
        <mass value="0.17"/>
        <inertia ixx="0.00004" ixy="0.0" ixz="0.0" iyy="0.00004" iyz="0.0" izz="0.00004"/>
      </inertial>
    </link>
    <joint name="FR_thigh_joint" type="revolute">
      <origin rpy="0 0 0" xyz="0 0 -0.01"/>
      <parent link="FR_hip"/>
      <child link="FR_thigh"/>
      <axis xyz="0 1 0"/>
      <dynamics damping="0.0" friction="0.0"/>
      <limit effort="7" lower="0.0" upper="0.9" velocity="7"/>
    </joint>
    <link name="FR_thigh">
      <visual>
         <origin rpy="0 1.57079632679 0" xyz="0 0 -0.0725"/>
         <geometry>
           <box size="0.145 0.04 0.02"/>
         </geometry>
         <material name="orange"/>
      </visual>
      <collision>
         <origin rpy="0 1.57079632679 0" xyz="0 0 -0.0725"/>
         <geometry>
            <box size="0.145 0.04 0.02"/>
         </geometry>
      </collision>
      <inertial>
        <origin rpy="0 0 0" xyz="0 0 0"/>
        <mass value="0.35"/>
        <inertia ixx="0.0012" ixy="0.0" ixz="0.0" iyy="0.001" iyz="0.0" izz="0.0004"/>
      </inertial>
    </link>
    <joint name="FR_calf_joint" type="revolute">
      <origin rpy="0 0 0" xyz="0 0 -0.1575"/>
      <parent link="FR_thigh"/>
      <child link="FR_calf"/>
      <axis xyz="0 1 0"/>
      <dynamics damping="0.0" friction="0.0"/>
      <limit effort="7" lower="-1.6" upper="-0.5" velocity="7"/>
    </joint>
    <link name="FR_calf">
      <visual>
         <origin rpy="0 1.57079632679 0" xyz="0 0 -0.075"/>
         <geometry>
           <box size="0.17 0.04 0.02"/>
         </geometry>
         <material name="orange"/>
      </visual>
      <collision>
         <origin rpy="0 1.57079632679 0" xyz="0 0 -0.085"/>
         <geometry>
            <box size="0.17 0.04 0.02"/>
         </geometry>
      </collision>
      <inertial>
        <origin rpy="0 0 0" xyz="0 0 0"/>
        <mass value="0.3"/>
        <inertia ixx="0.001" ixy="0.0" ixz="0.0" iyy="0.0008" iyz="0.0" izz="0.0003"/>
      </inertial>
    </link>
    <joint name="FR_foot_calf_fixed" type="fixed">
      <origin rpy="0 0 0" xyz="0 0 -0.1575"/>
      <parent link="FR_calf"/>
      <child link="FR_foot_fixed"/>
    </joint>
    <link name="FR_foot_fixed">
        <inertial>
            <origin rpy="0 0 0" xyz="0 0 0"/>
            <mass value="0.001"/>
            <inertia ixx="0.000001" ixy="0.0" ixz="0.0" iyy="0.000001" iyz="0.0" izz="0.000001"/>
        </inertial>
    </link>
    <joint name="FR_foot_FR_fixed" type="fixed">
        <parent link="FR_foot_fixed"/>
        <child link="FR_FOOT"/>
        <origin rpy="0 0 0" xyz="0 0 0"/>
    </joint>
    <link name="FR_FOOT">
      <visual>
        <origin rpy="1.57079632679 0 0" xyz="0 0 0"/>
        <geometry>
          <cylinder length="0.04" radius="0.01"/>
        </geometry>
        <material name="red"/>
      </visual>
      <collision>
        <origin rpy="1.57079632679 0 0" xyz="0 0 0"/>
        <geometry>
          <cylinder length="0.04" radius="0.01"/>
        </geometry>
      </collision>
      <inertial>
        <mass value="0.02"/>
        <inertia ixx="9.6e-06" ixy="0.0" ixz="0.0" iyy="9.6e-06" iyz="0.0" izz="9.6e-06"/>
      </inertial>
    </link>

    <!-- FL -->
    <joint name="FL_hip_joint" type="revolute">
      <origin rpy="0 0 0" xyz="0.16 0.127 0"/>
      <parent link="base"/>
      <child link="FL_hip"/>
      <axis xyz="1 0 0"/>
      <dynamics damping="0.0" friction="0.0"/>
      <limit effort="7" lower="-0.3" upper="0.3" velocity="7"/>
    </joint>
    <link name="FL_hip">
      <visual>
         <origin rpy="0 0 0" xyz="0 0 0"/>
         <geometry>
           <box size="0.04 0.04 0.02"/>
         </geometry>
         <material name="orange"/>
      </visual>
      <collision>
         <origin rpy="0 0 0" xyz="0 0 0"/>
         <geometry>
            <box size="0.04 0.04 0.02"/>
         </geometry>
      </collision>
      <inertial>
        <origin rpy="0 0 0" xyz="0 0 0"/>
        <mass value="0.17"/>
        <inertia ixx="0.00003" ixy="0.0" ixz="0.0" iyy="0.00003" iyz="0.0" izz="0.00003"/>
      </inertial>
    </link>
    <joint name="FL_thigh_joint" type="revolute">
      <origin rpy="0 0 0" xyz="0 0 -0.01"/>
      <parent link="FL_hip"/>
      <child link="FL_thigh"/>
      <axis xyz="0 1 0"/>
      <dynamics damping="0.0" friction="0.0"/>
      <limit effort="7" lower="0.0" upper="0.9" velocity="7"/>
    </joint>
    <link name="FL_thigh">
      <visual>
         <origin rpy="0 1.57079632679 0" xyz="0 0 -0.0725"/>
         <geometry>
           <box size="0.145 0.04 0.02"/>
         </geometry>
         <material name="orange"/>
      </visual>
      <collision>
         <origin rpy="0 1.57079632679 0" xyz="0 0 -0.0725"/>
         <geometry>
            <box size="0.145 0.04 0.02"/>
         </geometry>
      </collision>
      <inertial>
        <origin rpy="0 0 0" xyz="0 0 0"/>
        <mass value="0.35"/>
        <inertia ixx="0.0012" ixy="0.0" ixz="0.0" iyy="0.001" iyz="0.0" izz="0.0004"/>
      </inertial>
    </link>
    <joint name="FL_calf_joint" type="revolute">
      <origin rpy="0 0 0" xyz="0 0 -0.1575"/>
      <parent link="FL_thigh"/>
      <child link="FL_calf"/>
      <axis xyz="0 1 0"/>
      <dynamics damping="0.0" friction="0.0"/>
      <limit effort="7" lower="-1.6" upper="-0.5" velocity="7"/>
    </joint>
    <link name="FL_calf">
      <visual>
         <origin rpy="0 1.57079632679 0" xyz="0 0 -0.075"/>
         <geometry>
           <box size="0.17 0.04 0.02"/>
         </geometry>
         <material name="orange"/>
      </visual>
      <collision>
         <origin rpy="0 1.57079632679 0" xyz="0 0 -0.085"/>
         <geometry>
            <box size="0.17 0.04 0.02"/>
         </geometry>
      </collision>
      <inertial>
        <origin rpy="0 0 0" xyz="0 0 0"/>
        <mass value="0.3"/>
        <inertia ixx="0.001" ixy="0.0" ixz="0.0" iyy="0.0008" iyz="0.0" izz="0.0003"/>
      </inertial>
    </link>
    <joint name="FL_foot_calf_fixed" type="fixed">
      <origin rpy="0 0 0" xyz="0 0 -0.1575"/>
      <parent link="FL_calf"/>
      <child link="FL_foot_fixed"/>
    </joint>
    <link name="FL_foot_fixed">
        <inertial>
            <origin rpy="0 0 0" xyz="0 0 0"/>
            <mass value="0.001"/>
            <inertia ixx="0.000001" ixy="0.0" ixz="0.0" iyy="0.000001" iyz="0.0" izz="0.000001"/>
        </inertial>
    </link>
    <joint name="FL_foot_FL_fixed" type="fixed">
        <parent link="FL_foot_fixed"/>
        <child link="FL_FOOT"/>
        <origin rpy="0 0 0" xyz="0 0 0"/>
    </joint>
    <link name="FL_FOOT">
      <visual>
        <origin rpy="1.57079632679 0 0" xyz="0 0 0"/>
        <geometry>
          <cylinder length="0.04" radius="0.01"/>
        </geometry>
        <material name="red"/>
      </visual>
      <collision>
        <origin rpy="1.57079632679 0 0" xyz="0 0 0"/>
        <geometry>
          <cylinder length="0.04" radius="0.01"/>
        </geometry>
      </collision>
      <inertial>
        <mass value="0.02"/>
        <inertia ixx="9.6e-06" ixy="0.0" ixz="0.0" iyy="9.6e-06" iyz="0.0" izz="9.6e-06"/>
      </inertial>
    </link>

    <!-- RR -->
    <joint name="RR_hip_joint" type="revolute">
      <origin rpy="0 0 0" xyz="-0.16 -0.127 0"/>
      <parent link="base"/>
      <child link="RR_hip"/>
      <axis xyz="1 0 0"/>
      <dynamics damping="0.0" friction="0.0"/>
      <limit effort="7" lower="-0.3" upper="0.3" velocity="7"/>
    </joint>
    <link name="RR_hip">
      <visual>
         <origin rpy="0 0 0" xyz="0 0 0"/>
         <geometry>
           <box size="0.04 0.04 0.02"/>
         </geometry>
         <material name="orange"/>
      </visual>
      <collision>
         <origin rpy="0 0 0" xyz="0 0 0"/>
         <geometry>
            <box size="0.04 0.04 0.02"/>
         </geometry>
      </collision>
      <inertial>
        <origin rpy="0 0 0" xyz="0 0 0"/>
        <mass value="0.17"/>
        <inertia ixx="0.0012" ixy="0.0" ixz="0.0" iyy="0.001" iyz="0.0" izz="0.0004"/>
      </inertial>
    </link>
    <joint name="RR_thigh_joint" type="revolute">
      <origin rpy="0 0 0" xyz="0 0 -0.01"/>
      <parent link="RR_hip"/>
      <child link="RR_thigh"/>
      <axis xyz="0 1 0"/>
      <dynamics damping="0.0" friction="0.0"/>
      <limit effort="7" lower="0.0" upper="0.9" velocity="7"/>
    </joint>
    <link name="RR_thigh">
      <visual>
         <origin rpy="0 1.57079632679 0" xyz="0 0 -0.0725"/>
         <geometry>
           <box size="0.145 0.04 0.02"/>
         </geometry>
         <material name="orange"/>
      </visual>
      <collision>
         <origin rpy="0 1.57079632679 0" xyz="0 0 -0.0725"/>
         <geometry>
            <box size="0.145 0.04 0.02"/>
         </geometry>
      </collision>
      <inertial>
        <origin rpy="0 0 0" xyz="0 0 0"/>
        <mass value="0.35"/>
        <inertia ixx="0.0024529" ixy="0.0" ixz="0.0" iyy="0.0" iyz="0.0" izz="0.0024529"/>
      </inertial>
    </link>
    <joint name="RR_calf_joint" type="revolute">
      <origin rpy="0 0 0" xyz="0 0 -0.1575"/>
      <parent link="RR_thigh"/>
      <child link="RR_calf"/>
      <axis xyz="0 1 0"/>
      <dynamics damping="0.0" friction="0.0"/>
      <limit effort="7" lower="-1.6" upper="-0.5" velocity="7"/>
    </joint>
    <link name="RR_calf">
      <visual>
         <origin rpy="0 1.57079632679 0" xyz="0 0 -0.075"/>
         <geometry>
           <box size="0.17 0.04 0.02"/>
         </geometry>
         <material name="orange"/>
      </visual>
      <collision>
         <origin rpy="0 1.57079632679 0" xyz="0 0 -0.085"/>
         <geometry>
            <box size="0.17 0.04 0.02"/>
         </geometry>
      </collision>
      <inertial>
        <origin rpy="0 0 0" xyz="0 0 0"/>
        <mass value="0.3"/>
        <inertia ixx="0.001" ixy="0.0" ixz="0.0" iyy="0.0008" iyz="0.0" izz="0.0003"/>
      </inertial>
    </link>
    <joint name="RR_foot_calf_fixed" type="fixed">
      <origin rpy="0 0 0" xyz="0 0 -0.1575"/>
      <parent link="RR_calf"/>
      <child link="RR_foot_fixed"/>
    </joint>
    <link name="RR_foot_fixed">
        <inertial>
            <origin rpy="0 0 0" xyz="0 0 0"/>
            <mass value="0.001"/>
            <inertia ixx="0.000001" ixy="0.0" ixz="0.0" iyy="0.000001" iyz="0.0" izz="0.000001"/>
        </inertial>
    </link>
    <joint name="RR_foot_RR_fixed" type="fixed">
        <parent link="RR_foot_fixed"/>
        <child link="RR_FOOT"/>
        <origin rpy="0 0 0" xyz="0 0 0"/>
    </joint>
    <link name="RR_FOOT">
      <visual>
        <origin rpy="1.57079632679 0 0" xyz="0 0 0"/>
        <geometry>
          <cylinder length="0.04" radius="0.01"/>
        </geometry>
        <material name="red"/>
      </visual>
      <collision>
        <origin rpy="1.57079632679 0 0" xyz="0 0 0"/>
        <geometry>
          <cylinder length="0.04" radius="0.01"/>
        </geometry>
      </collision>
      <inertial>
        <mass value="0.02"/>
        <inertia ixx="9.6e-06" ixy="0.0" ixz="0.0" iyy="9.6e-06" iyz="0.0" izz="9.6e-06"/>
      </inertial>
    </link>

    <!-- RL -->
    <joint name="RL_hip_joint" type="revolute">
      <origin rpy="0 0 0" xyz="-0.16 0.127 0"/>
      <parent link="base"/>
      <child link="RL_hip"/>
      <axis xyz="1 0 0"/>
      <dynamics damping="0.0" friction="0.0"/>
      <limit effort="7" lower="-0.3" upper="0.3" velocity="7"/>
    </joint>
    <link name="RL_hip">
      <visual>
         <origin rpy="0 0 0" xyz="0 0 0"/>
         <geometry>
           <box size="0.04 0.04 0.02"/>
         </geometry>
         <material name="orange"/>
      </visual>
      <collision>
         <origin rpy="0 0 0" xyz="0 0 0"/>
         <geometry>
            <box size="0.04 0.04 0.02"/>
         </geometry>
      </collision>
      <inertial>
        <origin rpy="0 0 0" xyz="0 0 0"/>
        <mass value="0.17"/>
        <inertia ixx="0.00003" ixy="0.0" ixz="0.0" iyy="0.00003" iyz="0.0" izz="0.00003"/>
      </inertial>
    </link>
    <joint name="RL_thigh_joint" type="revolute">
      <origin rpy="0 0 0" xyz="0 0 -0.01"/>
      <parent link="RL_hip"/>
      <child link="RL_thigh"/>
      <axis xyz="0 1 0"/>
      <dynamics damping="0.0" friction="0.0"/>
      <limit effort="7" lower="0.0" upper="0.9" velocity="7"/>
    </joint>
    <link name="RL_thigh">
      <visual>
         <origin rpy="0 1.57079632679 0" xyz="0 0 -0.0725"/>
         <geometry>
           <box size="0.145 0.04 0.02"/>
         </geometry>
         <material name="orange"/>
      </visual>
      <collision>
         <origin rpy="0 1.57079632679 0" xyz="0 0 -0.0725"/>
         <geometry>
            <box size="0.145 0.04 0.02"/>
         </geometry>
      </collision>
      <inertial>
        <origin rpy="0 0 0" xyz="0 0 0"/>
        <mass value="0.35"/>
        <inertia ixx="0.0012" ixy="0.0" ixz="0.0" iyy="0.001" iyz="0.0" izz="0.0004"/>
      </inertial>
    </link>
    <joint name="RL_calf_joint" type="revolute">
      <origin rpy="0 0 0" xyz="0 0 -0.1575"/>
      <parent link="RL_thigh"/>
      <child link="RL_calf"/>
      <axis xyz="0 1 0"/>
      <dynamics damping="0.0" friction="0.0"/>
      <limit effort="7" lower="-1.6" upper="-0.5" velocity="7"/>
    </joint>
    <link name="RL_calf">
      <visual>
         <origin rpy="0 1.57079632679 0" xyz="0 0 -0.075"/>
         <geometry>
           <box size="0.17 0.04 0.02"/>
         </geometry>
         <material name="orange"/>
      </visual>
      <collision>
         <origin rpy="0 1.57079632679 0" xyz="0 0 -0.085"/>
         <geometry>
            <box size="0.17 0.04 0.02"/>
         </geometry>
      </collision>
      <inertial>
        <origin rpy="0 0 0" xyz="0 0 0"/>
        <mass value="0.3"/>
        <inertia ixx="0.001" ixy="0.0" ixz="0.0" iyy="0.0008" iyz="0.0" izz="0.0003"/>
      </inertial>
    </link>
    <joint name="RL_foot_calf_fixed" type="fixed">
      <origin rpy="0 0 0" xyz="0 0 -0.1575"/>
      <parent link="RL_calf"/>
      <child link="RL_foot_fixed"/>
    </joint>
    <link name="RL_foot_fixed">
        <inertial>
            <origin rpy="0 0 0" xyz="0 0 0"/>
            <mass value="0.001"/>
            <inertia ixx="0.000001" ixy="0.0" ixz="0.0" iyy="0.000001" iyz="0.0" izz="0.000001"/>
        </inertial>
    </link>
    <joint name="RL_foot_RL_fixed" type="fixed">
        <parent link="RL_foot_fixed"/>
        <child link="RL_FOOT"/>
        <origin rpy="0 0 0" xyz="0 0 0"/>
    </joint>
    <link name="RL_FOOT">
      <visual>
        <origin rpy="1.57079632679 0 0" xyz="0 0 0"/>
        <geometry>
          <cylinder length="0.04" radius="0.01"/>
        </geometry>
        <material name="red"/>
      </visual>
      <collision>
        <origin rpy="1.57079632679 0 0" xyz="0 0 0"/>
        <geometry>
          <cylinder length="0.04" radius="0.01"/>
        </geometry>
      </collision>
      <inertial>
        <mass value="0.02"/>
        <inertia ixx="9.6e-06" ixy="0.0" ixz="0.0" iyy="9.6e-06" iyz="0.0" izz="9.6e-06"/>
      </inertial>
    </link>
</robot>
